Workbook

Sheet 표지
A1: 스포이즘 ERP — 데이터 정의서
A2: 테이블 정의서 · 코드 정의서 · 관계 · 제약
A4: 프로젝트 | B4: 스포이즘 ERP — 아파트·오피스텔 커뮤니티 시설 위탁운영 관리 시스템
A5: 문서 | B5: 데이터 정의서
A6: DBMS | B6: PostgreSQL(Supabase, 서울 리전) · ORM: Prisma 5
A7: 작성일 | B7: 2026-10-20
A8: 기준 | B8: 2026-10-20 저장소(dev 브랜치) — apps/api/prisma/schema.prisma, migrations/*.sql에서 자동 생성
A9: 규모 | B9: 테이블 34개 · 컬럼 289개 · 코드(enum) 27종 · CHECK 21개 · 트리거 8개
A10: 미사용 테이블 | B10: 읽음 확인(PostReadReceipt), 프로그램 시간표 틀(ProgramScheduleTemplate), 혼잡도 기록(CongestionSnapshot), 시설 입퇴장(FacilityCheckIn), 개인 예외 권한(AccountPermission) — 스키마에만 있고 코드가 읽거나 쓰지 않는다. 사유는 테이블 목록의 설명(요구사항 정의서 "미구현"·"범위 제외" 탭)
A12: 시트 구성
A13: 테이블 목록 | B13: 테이블별 도메인·논리명·설명·컬럼 수·사용 여부
A14: 컬럼 정의 | B14: 전 테이블 컬럼 — 타입·PK·FK·NULL·기본값·UNIQUE·설명(필터로 테이블별 조회)
A15: 관계 | B15: 외래키 — 자식 테이블, 참조 컬럼, 부모 테이블, 삭제 시 동작
A16: 코드 정의 | B16: enum 코드값과 의미, 사용하는 컬럼
A17: 인덱스·유일 | B17: 유일 제약, 부분 유일 인덱스(조건부), 조회 인덱스
A18: DB 규칙 | B18: CHECK 제약과 지점 일치 트리거 — 앱 검증과 이중으로 데이터 정합성을 지킨다

Sheet 테이블 목록
A1: 테이블 목록
A2: 컬럼 수는 "컬럼 정의" 시트를 세는 수식이다
A4: No | B4: 도메인 | C4: 테이블(물리명) | D4: 논리명 | E4: 설명 | F4: 컬럼 수 | G4: 사용 여부
A5: 1 | B5: 권한관리 | C5: Account | D5: 계정 | E5: 로그인 주체. 역할 4개(본사 관리자·지점 관리자·직원·회원) 중 하나를 가진다 | F5: =COUNTIF('컬럼 정의'!$B:$B,C5) | G5: 사용
A6: 2 | B6: 권한관리 | C6: RefreshToken | D6: 리프레시 토큰 | E6: 로그인 유지용 토큰(1회용 교체). 원문 대신 해시를 저장 | F6: =COUNTIF('컬럼 정의'!$B:$B,C6) | G6: 사용
A7: 3 | B7: 권한관리 | C7: Branch | D7: 지점(위탁계약 현장) | E7: 아파트·오피스텔과 맺은 위탁운영 계약 현장. 계약 상대방·기간·상태를 가진다 | F7: =COUNTIF('컬럼 정의'!$B:$B,C7) | G7: 사용
A8: 4 | B8: 인사정보관리 | C8: Staff | D8: 직원 | E8: 본사가 채용한 인력. 현재 파견 지점을 캐시로 가진다 | F8: =COUNTIF('컬럼 정의'!$B:$B,C8) | G8: 사용
A9: 5 | B9: 인사정보관리 | C9: StaffAssignment | D9: 파견 이력 | E9: 직원이 언제 어느 지점에 파견됐는지. 진행 중 파견은 직원당 1건 | F9: =COUNTIF('컬럼 정의'!$B:$B,C9) | G9: 사용
A10: 6 | B10: 인사정보관리 | C10: StaffProfileChangeRequest | D10: 인사 변경 신청 | E10: 직원 본인의 인사정보 변경 신청과 관리자 1단계 승인(D11, ADR-STF-09) | F10: =COUNTIF('컬럼 정의'!$B:$B,C10) | G10: 사용
A11: 7 | B11: 근태관리 | C11: AttendanceRecord | D11: 근태 기록 | E11: 직원별 하루 1건의 출퇴근·상태 기록 | F11: =COUNTIF('컬럼 정의'!$B:$B,C11) | G11: 사용
A12: 8 | B12: 근태관리 | C12: LeaveRequest | D12: 휴가 신청 | E12: 연차·병가 등 휴가 신청과 승인·반려 | F12: =COUNTIF('컬럼 정의'!$B:$B,C12) | G12: 사용
A13: 9 | B13: 근태관리 | C13: LeaveBalance | D13: 연차 잔여 | E13: 직원·연도별 부여 일수와 사용 일수 | F13: =COUNTIF('컬럼 정의'!$B:$B,C13) | G13: 사용
A14: 10 | B14: 근태관리 | C14: WorkLog | D14: 업무일지 | E14: 직원별 하루 업무 기록 | F14: =COUNTIF('컬럼 정의'!$B:$B,C14) | G14: 사용
A15: 11 | B15: 게시판 | C15: Post | D15: 게시글 | E15: 본사→현장, 현장→이용자 공지. 지점 공지는 대상 시설을 지정할 수 있다(게시판 ADR-BRD-05) | F15: =COUNTIF('컬럼 정의'!$B:$B,C15) | G15: 사용
A16: 12 | B16: 게시판 | C16: Attachment | D16: 첨부파일 | E16: 게시글 첨부(교육자료·이미지 등). 파일은 저장소(Supabase Storage)에 두고 경로만 저장한다(ADR-BRD-04, D57) | F16: =COUNTIF('컬럼 정의'!$B:$B,C16) | G16: 사용
... A38: 34 | B38: 공통 | C38: AccountPermission | D38: 개인 예외 권한 | E38: 한 사람의 기능×동작 권한을 역할 기본값과 다르게 허용·차단(D60). 역할 상한은 넘지 못한다 | F38: =COUNTIF('컬럼 정의'!$B:$B,C38) | G38: 미사용(설계만)
E39: 합계 | F39: =SUM(F5:F38)

Sheet 컬럼 정의
A1: 컬럼 정의
A2: 헤더의 필터로 테이블·도메인별로 볼 수 있다. 같은 테이블은 같은 줄무늬
A4: 도메인 | B4: 테이블 | C4: 컬럼 | D4: Prisma 타입 | E4: DB 타입 | F4: PK | G4: FK(참조) | H4: NULL 허용 | I4: 기본값 | J4: UNIQUE | K4: 설명
A5: 권한관리 | B5: Account | C5: id | D5: String | E5: text | F5: Y | H5: N | I5: uuid() | K5: 식별자(UUID)
A6: 권한관리 | B6: Account | C6: email | D6: String | E6: text | H6: N | K6: 부분 unique(활성 계정끼리만) — 파일 상단 주석 1). findUnique 불가, findFirst 사용
A7: 권한관리 | B7: Account | C7: passwordHash | D7: String | E7: text | H7: N | K7: 비밀번호 해시(bcrypt)
A8: 권한관리 | B8: Account | C8: role | D8: Role | E8: enum Role | H8: N | K8: 역할
A9: 권한관리 | B9: Account | C9: name | D9: String | E9: text | H9: N | K9: SUPER_ADMIN은 Staff/Member 프로필이 없어 이름을 여기 직접 둔다 — Staff/Member 보유 계정도 조회 편의상 함께 저장(항상 그쪽 name과 동기화)
A10: 권한관리 | B10: Account | C10: isActive | D10: Boolean | E10: boolean | H10: N | I10: true | K10: 사용 여부
A11: 권한관리 | B11: Account | C11: failedLoginCount | D11: Int | E11: integer | H11: N | I11: 0 | K11: 연속 로그인 실패 횟수(미사용)
A12: 권한관리 | B12: Account | C12: lockedUntil | D12: DateTime? | E12: timestamp(3) | H12: Y | K12: 로그인 잠금 해제 시각(미사용)
A13: 권한관리 | B13: Account | C13: lastLoginAt | D13: DateTime? | E13: timestamp(3) | H13: Y | K13: 마지막 로그인 일시
A14: 권한관리 | B14: Account | C14: createdAt | D14: DateTime | E14: timestamp(3) | H14: N | I14: now() | K14: 생성 일시
A15: 권한관리 | B15: Account | C15: updatedAt | D15: DateTime | E15: timestamp(3) | H15: N | I15: (수정 시 자동) | K15: 수정 일시
A16: 권한관리 | B16: RefreshToken | C16: id | D16: String | E16: text | F16: Y | H16: N | I16: uuid() | K16: 식별자(UUID)
A17: 권한관리 | B17: RefreshToken | C17: accountId | D17: String | E17: text | G17: Account.id | H17: N | K17: 계정 ID
A18: 권한관리 | B18: RefreshToken | C18: tokenHash | D18: String | E18: text | H18: N | K18: 토큰 해시
A19: 권한관리 | B19: RefreshToken | C19: expiresAt | D19: DateTime | E19: timestamp(3) | H19: N | K19: 만료 일시
A20: 권한관리 | B20: RefreshToken | C20: revokedAt | D20: DateTime? | E20: timestamp(3) | H20: Y | K20: 폐기 일시
A21: 권한관리 | B21: RefreshToken | C21: createdAt | D21: DateTime | E21: timestamp(3) | H21: N | I21: now() | K21: 생성 일시
A22: 권한관리 | B22: Branch | C22: id | D22: String | E22: text | F22: Y | H22: N | I22: uuid() | K22: 식별자(UUID)
A23: 권한관리 | B23: Branch | C23: name | D23: String | E23: text | H23: N | K23: 이름
A24: 권한관리 | B24: Branch | C24: code | D24: String | E24: text | H24: N | J24: Y | K24: 지점 코드 — memberNo/staffCode 생성에 사용 (예: "SEOCHO"). 1-3(staffCode)/1-6(memberNo)문서 참고
A25: 권한관리 | B25: Branch | C25: address | D25: String? | E25: text | H25: Y | K25: 주소
A26: 권한관리 | B26: Branch | C26: region | D26: String | E26: text | H26: N | K26: 광역 단위(예: "서울", "경기") — address(상세 주소)와 별개로 대시보드 지역별 그룹핑에 사용
A27: 권한관리 | B27: Branch | C27: phone | D27: String? | E27: text | H27: Y | K27: 연락처
A28: 권한관리 | B28: Branch | C28: standardCheckInTime | D28: String? | E28: text | H28: Y | K28: "HH:mm" — 근태관리 문서 지각 판정 기준
A29: 권한관리 | B29: Branch | C29: cancellationDeadlineHours | D29: Int? | E29: integer | H29: Y | K29: 예약 무료취소 기준 시간(예: 24) — nullable이면 전역 기본값 사용, 예약및결제 A-6 참고. architecture/entities.md §2-1의 cancellationPolicy를 단순 컬럼으로 구현
A30: 권한관리 | B30: Branch | C30: isActive | D30: Boolean | E30: boolean | H30: N | I30: true | K30: 사용 여부
A31: 권한관리 | B31: Branch | C31: contractPartner | D31: String | E31: text | H31: N | K31: 위탁계약 상대방(예: "서초 OO아파트 입주자대표회의") — 관리자 전용 정보
A32: 권한관리 | B32: Branch | C32: contractStartAt | D32: DateTime | E32: date | H32: N | K32: 계약 시작일
A33: 권한관리 | B33: Branch | C33: contractEndAt | D33: DateTime? | E33: date | H33: Y | K33: 계약 종료일
A34: 권한관리 | B34: Branch | C34: contractStatus | D34: BranchContractStatus | E34: enum BranchContractStatus | H34: N | I34: ACTIVE | K34: 계약 상태
A35: 권한관리 | B35: Branch | C35: createdAt | D35: DateTime | E35: timestamp(3) | H35: N | I35: now() | K35: 생성 일시
A36: 권한관리 | B36: Branch | C36: updatedAt | D36: DateTime | E36: timestamp(3) | H36: N | I36: (수정 시 자동) | K36: 수정 일시
A37: 인사정보관리 | B37: Staff | C37: id | D37: String | E37: text | F37: Y | H37: N | I37: uuid() | K37: 식별자(UUID)
A38: 인사정보관리 | B38: Staff | C38: accountId | D38: String | E38: text | G38: Account.id | H38: N | J38: Y | K38: 계정 ID
A39: 인사정보관리 | B39: Staff | C39: branchId | D39: String | E39: text | G39: Branch.id | H39: N | K39: 지점 ID
A40: 인사정보관리 | B40: Staff | C40: staffCode | D40: String | E40: text | H40: N | J40: Y | K40: 직원 코드
A41: 인사정보관리 | B41: Staff | C41: name | D41: String | E41: text | H41: N | K41: 이름
...

Sheet 관계
A1: 관계(외래키)
A2: 삭제 시 동작: Cascade = 부모 삭제 시 함께 삭제, SetNull = NULL로, 제한(기본) = 자식이 있으면 부모 삭제 불가
A4: 자식 테이블 | B4: FK 컬럼 | C4: 부모 테이블 | D4: 삭제 시 동작 | E4: 관계 필드명
A5: RefreshToken | B5: accountId | C5: Account | D5: Cascade | E5: account
A6: Staff | B6: accountId | C6: Account | D6: Cascade | E6: account
A7: Staff | B7: branchId | C7: Branch | D7: 제한(기본) | E7: branch
A8: StaffAssignment | B8: staffId | C8: Staff | D8: Cascade | E8: staff
A9: StaffAssignment | B9: branchId | C9: Branch | D9: 제한(기본) | E9: branch
A10: StaffAssignment | B10: assignedBy | C10: Account | D10: 제한(기본) | E10: assignedByAccount
A11: StaffProfileChangeRequest | B11: staffId | C11: Staff | D11: Cascade | E11: staff
A12: AttendanceRecord | B12: staffId | C12: Staff | D12: Cascade | E12: staff
A13: AttendanceRecord | B13: branchId | C13: Branch | D13: 제한(기본) | E13: branch
A14: LeaveRequest | B14: staffId | C14: Staff | D14: Cascade | E14: staff
A15: LeaveBalance | B15: staffId | C15: Staff | D15: Cascade | E15: staff
... A54: AccountPermission | B54: accountId | C54: Account | D54: Cascade | E54: account

Sheet 코드 정의
A1: 코드 정의(enum)
A2: 코드값은 DB에 영문으로 저장되고 화면에는 의미(한글)로 표시된다
A4: 코드 그룹 | B4: 도메인 | C4: 코드값 | D4: 의미 | E4: 사용 컬럼
A5: Role | B5: 공통 | C5: SUPER_ADMIN | E5: Account.role, RolePermission.role
A6: Role | B6: 공통 | C6: BRANCH_ADMIN | E6: Account.role, RolePermission.role
A7: Role | B7: 공통 | C7: STAFF | D7: 지점 소속 일반 직원(트레이너 등) — 관리 권한 없이 본인 근태/휴가/업무일지만 셀프서비스 (권한관리 A-7) | E7: Account.role, RolePermission.role
A8: Role | B8: 공통 | C8: MEMBER | E8: Account.role, RolePermission.role
A9: BranchContractStatus | B9: 권한관리 | C9: ACTIVE | E9: Branch.contractStatus
A10: BranchContractStatus | B10: 권한관리 | C10: RENEWAL_DUE | E10: Branch.contractStatus
A11: BranchContractStatus | B11: 권한관리 | C11: EXPIRED | E11: Branch.contractStatus
A12: BranchContractStatus | B12: 권한관리 | C12: TERMINATED | E12: Branch.contractStatus
A13: StaffStatus | B13: 인사정보관리 | C13: ACTIVE | D13: 재직 | E13: Staff.status
A14: StaffStatus | B14: 인사정보관리 | C14: ON_LEAVE | D14: 휴직 | E14: Staff.status
A15: StaffStatus | B15: 인사정보관리 | C15: RESIGNED | D15: 퇴사 | E15: Staff.status
A16: ChangeRequestStatus | B16: 인사정보관리 | C16: PENDING | E16: StaffProfileChangeRequest.status
A17: ChangeRequestStatus | B17: 인사정보관리 | C17: APPROVED | E17: StaffProfileChangeRequest.status
A18: ChangeRequestStatus | B18: 인사정보관리 | C18: REJECTED | E18: StaffProfileChangeRequest.status
A19: AttendanceStatus | B19: 근태관리 | C19: NORMAL | D19: 정상 | E19: AttendanceRecord.status
A20: AttendanceStatus | B20: 근태관리 | C20: LATE | D20: 지각 | E20: AttendanceRecord.status
A21: AttendanceStatus | B21: 근태관리 | C21: EARLY_LEAVE | D21: 조퇴 | E21: AttendanceRecord.status
A22: AttendanceStatus | B22: 근태관리 | C22: ABSENT | D22: 결근 | E22: AttendanceRecord.status
A23: AttendanceStatus | B23: 근태관리 | C23: ON_LEAVE | D23: 휴가 | E23: AttendanceRecord.status
A24: LeaveType | B24: 근태관리 | C24: ANNUAL | D24: 연차 | E24: LeaveRequest.type
A25: LeaveType | B25: 근태관리 | C25: SICK | D25: 병가 | E25: LeaveRequest.type
A26: LeaveType | B26: 근태관리 | C26: FAMILY_EVENT | D26: 경조사 | E26: LeaveRequest.type
A27: LeaveType | B27: 근태관리 | C27: OTHER | E27: LeaveRequest.type
A28: LeaveStatus | B28: 근태관리 | C28: PENDING | E28: LeaveRequest.status
A29: LeaveStatus | B29: 근태관리 | C29: APPROVED | E29: LeaveRequest.status
A30: LeaveStatus | B30: 근태관리 | C30: REJECTED | E30: LeaveRequest.status
A31: PostScope | B31: 게시판 | C31: HQ_TO_BRANCH | E31: Post.scope
A32: PostScope | B32: 게시판 | C32: BRANCH_TO_MEMBER | E32: Post.scope
A33: PostCategory | B33: 게시판 | C33: NOTICE | D33: 공지 | E33: Post.category
A34: PostCategory | B34: 게시판 | C34: TRAINING_MATERIAL | D34: 교육자료 | E34: Post.category
A35: PostCategory | B35: 게시판 | C35: EVENT | D35: 이벤트 | E35: Post.category
A36: PostCategory | B36: 게시판 | C36: OTHER | E36: Post.category
A37: MemberStatus | B37: 회원관리 | C37: ACTIVE | D37: 활성 | E37: Member.status
A38: MemberStatus | B38: 회원관리 | C38: DORMANT | D38: 휴면 | E38: Member.status
A39: MemberStatus | B39: 회원관리 | C39: WITHDRAWN | D39: 탈퇴 | E39: Member.status
A40: EnrollmentStatus | B40: 회원관리 | C40: ACTIVE | E40: CourseEnrollment.status
A41: EnrollmentStatus | B41: 회원관리 | C41: COMPLETED | E41: CourseEnrollment.status
...

Sheet 인덱스·유일
A1: 인덱스·유일 제약
A2: 부분 유일 인덱스는 Prisma 스키마로 표현할 수 없어 마이그레이션 SQL에만 있다(조건을 만족하는 행끼리만 유일)
A4: 테이블 | B4: 종류 | C4: 컬럼 | D4: 조건 | E4: 출처
A5: Account | B5: 부분 유일(UNIQUE … WHERE) | C5: email | D5: isActive | E5: 20260929002914_d27_lambda_readiness
A6: Account | B6: 인덱스 | C6: email | E6: 스키마
A7: Account | B7: 인덱스 | C7: role | E7: 스키마
A8: RefreshToken | B8: 인덱스 | C8: accountId | E8: 스키마
A9: Branch | B9: 유일(UNIQUE) | C9: code | E9: 스키마
A10: Branch | B10: 인덱스 | C10: isActive | E10: 스키마
A11: Branch | B11: 인덱스 | C11: contractStatus | E11: 스키마
A12: Branch | B12: 인덱스 | C12: contractEndAt | E12: 스키마
A13: Branch | B13: 인덱스 | C13: region | E13: 스키마
A14: Staff | B14: 유일(UNIQUE) | C14: accountId | E14: 스키마
A15: Staff | B15: 유일(UNIQUE) | C15: staffCode | E15: 스키마
A16: Staff | B16: 인덱스 | C16: branchId | E16: 스키마
A17: Staff | B17: 인덱스 | C17: status | E17: 스키마
A18: StaffAssignment | B18: 부분 유일(UNIQUE … WHERE) | C18: staffId | D18: endDate IS NULL | E18: 20260929002914_d27_lambda_readiness
A19: StaffAssignment | B19: 인덱스 | C19: staffId,endDate | E19: 스키마
A20: StaffAssignment | B20: 인덱스 | C20: branchId,startDate | E20: 스키마
A21: StaffProfileChangeRequest | B21: 인덱스 | C21: staffId,status | E21: 스키마
A22: AttendanceRecord | B22: 유일(UNIQUE) | C22: staffId,date | E22: 스키마
A23: AttendanceRecord | B23: 인덱스 | C23: staffId,date | E23: 스키마
A24: AttendanceRecord | B24: 인덱스 | C24: branchId | E24: 스키마
A25: LeaveRequest | B25: 인덱스 | C25: staffId,status | E25: 스키마
A26: LeaveBalance | B26: 유일(UNIQUE) | C26: staffId,year | E26: 스키마
A27: WorkLog | B27: 유일(UNIQUE) | C27: staffId,date | E27: 스키마
A28: Post | B28: 인덱스 | C28: scope,branchId,publishedAt | E28: 스키마
A29: Attachment | B29: 인덱스 | C29: postId | E29: 스키마
A30: PostReadReceipt | B30: 유일(UNIQUE) | C30: postId,accountId | E30: 스키마
... A44: ScheduleSlot | B44: 인덱스 | C44: programId,date | E44: 스키마
A45: Reservation | B45: 부분 유일(UNIQUE … WHERE) | C45: memberId, scheduleSlotId | D45: status IN ('REQUESTED', 'CONFIRMED') | E45: 20260929002914_d27_lambda_readiness
A46: Reservation | B46: 인덱스 | C46: memberId,scheduleSlotId | E46: 스키마
A47: Reservation | B47: 인덱스 | C47: scheduleSlotId,status | E47: 스키마
A48: Reservation | B48: 인덱스 | C48: memberId,status | E48: 스키마
A49: Payment | B49: 유일(UNIQUE) | C49: reservationId | E49: 스키마
A50: Payment | B50: 인덱스 | C50: memberId | E50: 스키마
A51: Facility | B51: 인덱스 | C51: branchId | E51: 스키마
A52: CongestionSnapshot | B52: 인덱스 | C52: facilityId,recordedAt | E52: 스키마
A53: FacilityCheckIn | B53: 인덱스 | C53: facilityId,checkOutAt | E53: 스키마
A54: Asset | B54: 유일(UNIQUE) | C54: assetCode | E54: 스키마
...

Sheet DB 규칙
A1: DB 규칙 — CHECK 제약 · 트리거
A2: 앱이 먼저 검증해 400/409를 내고, DB가 한 번 더 막는다(D28). 규칙 목록·원칙: architecture/data-integrity.md
A4: CHECK 제약 21개
A5: 테이블 | B5: 제약명 | C5: 조건 | D5: 근거·설명 | E5: 마이그레이션
A6: Program | B6: Program_paid_session_capacity_ck | C6: pricingType <> 'PAID_SESSION' OR (capacity IS NOT NULL AND capacity >= 1) | D6: ADR-PRG-01: PAID_SESSION은 정원 1명 이상 필수(assertCapacityForPricingType), 정원·가격은 음수 불가(DTO @Min(0)) | E6: 20260929004339_d28_integrity_checks
A7: Program | B7: Program_capacity_nonneg_ck | C7: capacity IS NULL OR capacity >= 0 | D7: ADR-PRG-01: PAID_SESSION은 정원 1명 이상 필수(assertCapacityForPricingType), 정원·가격은 음수 불가(DTO @Min(0)) | E7: 20260929004339_d28_integrity_checks
A8: Program | B8: Program_price_nonneg_ck | C8: price >= 0 | D8: ADR-PRG-01: PAID_SESSION은 정원 1명 이상 필수(assertCapacityForPricingType), 정원·가격은 음수 불가(DTO @Min(0)) | E8: 20260929004339_d28_integrity_checks
A9: ScheduleSlot | B9: ScheduleSlot_capacity_positive_ck | C9: capacity >= 1 | D9: ADR-RSV-01 전제: 회차 정원은 1 이상(CreateScheduleSlotDto @Min(1)) | E9: 20260929004339_d28_integrity_checks
A10: Payment | B10: Payment_amount_split_ck | C10: amount >= 0 AND supplyAmount >= 0 AND vat >= 0 AND supplyAmount + vat = amount | D10: 불변규칙 4(결제 금액 서버 계산): 공급가액 + 부가세 = 결제금액, 음수 불가 | E10: 20260929004339_d28_integrity_checks
A11: PTSession | B11: PTSession_usage_range_ck | C11: totalSessions >= 1 AND usedSessions >= 0 AND usedSessions <= totalSessions | D11: ADR-MEM-03: PT 사용 횟수는 0 이상 총 횟수 이하(usePTSession 소진 시 409), 총 횟수 1 이상(DTO @Min(1)) | E11: 20260929004339_d28_integrity_checks
A12: Post | B12: Post_branch_notice_visible_ck | C12: scope <> 'BRANCH_TO_MEMBER' OR (visibleToMember AND branchId IS NOT NULL) | D12: ADR-BRD-01: 지점 공지(BRANCH_TO_MEMBER)는 항상 회원 공개이고 지점이 있어야 한다(createPost가 강제) | E12: 20260929004339_d28_integrity_checks
A13: Facility | B13: Facility_congestion_range_ck | C13: capacity >= 1 AND currentCount >= 0 AND level BETWEEN 1 AND 5 | D13: 정원 1 이상(DTO @Min(1)), 현재 인원 0 이상(ManualCongestionDto @Min(0)), 단계 1~5(computeCongestionLevel) | E13: 20260929004339_d28_integrity_checks
A14: CongestionSnapshot | B14: CongestionSnapshot_range_ck | C14: capacity >= 1 AND currentCount >= 0 AND level BETWEEN 1 AND 5 | D14: 정원 1 이상(DTO @Min(1)), 현재 인원 0 이상(ManualCongestionDto @Min(0)), 단계 1~5(computeCongestionLevel) | E14: 20260929004339_d28_integrity_checks
A15: Asset | B15: Asset_quantity_ck | C15: quantity >= 0 AND (assetType <> 'FIXED_ASSET' OR quantity = 1) | D15: 고정자산은 수량 1(createAsset·updateAsset), 수량·취득가액 음수 불가, 내용연수 1 이상(DTO) | E15: 20260929004339_d28_integrity_checks
A16: Asset | B16: Asset_amounts_nonneg_ck | C16: acquisitionCost >= 0 AND (usefulLifeYears IS NULL OR usefulLifeYears >= 1) | D16: 고정자산은 수량 1(createAsset·updateAsset), 수량·취득가액 음수 불가, 내용연수 1 이상(DTO) | E16: 20260929004339_d28_integrity_checks
... A26: RolePermission | B26: RolePermission_role_check | C26: role IN ('BRANCH_ADMIN', 'STAFF') | D26: 세부 권한 표는 지점 관리자·직원만 다룬다(본사는 항상 전부, 회원은 본인 화면만 — D60 결정 2). | E26: 20261020135659_d60_permission_matrix
A28: 지점 일치 트리거 8개 — 연결된 데이터는 같은 지점이어야 한다
A29: 테이블 | B29: 트리거명 | C29: 시점·대상 | D29: 설명 | E29: 마이그레이션
A30: Program | B30: program_branch_consistency | C30: BEFORE INSERT OR UPDATE OF branchId, facilityId, instructorId | D30: ADR-PRG-03(assertFacilityInBranch·assertInstructorInBranch): 프로그램의 시설·강사는 같은 지점 | E30: 20260929005902_d28_branch_consistency_triggers
A31: Member | B31: member_assigned_staff_branch | C31: BEFORE INSERT OR UPDATE OF branchId, assignedStaffId | D31: MEM-T02(assertStaffInBranch): 회원의 담당 직원은 같은 지점 | E31: 20260929005902_d28_branch_consistency_triggers
A32: CourseEnrollment | B32: course_enrollment_branch | C32: BEFORE INSERT OR UPDATE OF memberId, programId | D32: ADR-MEM-03(assertProgramInBranch): 수강·PT 세션의 프로그램은 회원과 같은 지점 — 두 테이블이 같은 함수를 쓴다 | E32: 20260929005902_d28_branch_consistency_triggers
A33: PTSession | B33: pt_session_branch | C33: BEFORE INSERT OR UPDATE OF memberId, programId | D33: ADR-MEM-03(assertProgramInBranch): 수강·PT 세션의 프로그램은 회원과 같은 지점 — 두 테이블이 같은 함수를 쓴다 | E33: 20260929005902_d28_branch_consistency_triggers
A34: Reservation | B34: reservation_branch | C34: BEFORE INSERT OR UPDATE OF memberId, scheduleSlotId | D34: DI-02에서 발견한 공백(createReservation MEMBER_BRANCH_MISMATCH): 예약 회차의 프로그램은 회원과 같은 지점 | E34: 20260929005902_d28_branch_consistency_triggers
A35: Instructor | B35: instructor_staff_branch | C35: BEFORE INSERT OR UPDATE OF branchId, staffId | D35: ADR-STF-04: 강사 프로필에 연결된 직원은 같은 지점(파견 시 연결을 해제해야 한다) | E35: 20260929005902_d28_branch_consistency_triggers
A36: Staff | B36: staff_branch_move | C36: BEFORE UPDATE OF branchId | D36: ADR-STF-04 A안을 DB가 강제한다 — 담당 회원 해제·강사 프로필 연결 해제를 같은 트랜잭션에서 **먼저** 하지 않으면 Staff.branchId 갱신이 거부된다. (Facility·Instructor·Program의 branchId를 바꾸는 경로는 앱에 없어 역방향은 두지 않았다.) | E36: 20260929005902_d28_branch_consistency_triggers
A37: Post | B37: post_facility_branch | C37: BEFORE INSERT OR UPDATE OF branchId, facilityId | D37: D28 DI-02 방식 — 공지의 시설은 공지와 같은 지점(전체 공지 branchId=null에는 시설을 둘 수 없다). 앱이 먼저 403/400을 내고(BranchScopeGuard·PostService), 트리거는 최종 방어선이다. | E37: 20261020120300_f43_post_facility
